<?xml version="1.0" encoding="UTF-8"?>
<testng-results ignored="0" total="5" passed="1" failed="4" skipped="0">
  <reporter-output>
  </reporter-output>
  <suite started-at="2021-12-15T14:16:15 PET" name="Default suite" finished-at="2021-12-15T14:16:25 PET" duration-ms="10556">
    <groups>
    </groups>
    <test started-at="2021-12-15T14:16:15 PET" name="Default test" finished-at="2021-12-15T14:16:25 PET" duration-ms="10556">
      <class name="com.automation.testng.Login">
        <test-method is-config="true" signature="LoginConnection()[pri:0, instance:com.automation.testng.Login@4d465b11]" started-at="2021-12-15T14:16:15 PET" name="LoginConnection" finished-at="2021-12-15T14:16:18 PET" duration-ms="3336" status="PASS">
          <reporter-output>
          </reporter-output>
        </test-method> <!-- LoginConnection -->
        <test-method signature="LogIn_CorreoInvalido()[pri:0, instance:com.automation.testng.Login@4d465b11]" started-at="2021-12-15T14:16:18 PET" name="LogIn_CorreoInvalido" finished-at="2021-12-15T14:16:18 PET" duration-ms="207" status="FAIL">
          <exception class="java.lang.AssertionError">
            <message>
              <![CDATA[expected [true] but found [false]]]>
            </message>
            <full-stacktrace>
              <![CDATA[java.lang.AssertionError: expected [true] but found [false]
at org.testng.Assert.fail(Assert.java:99)
at org.testng.Assert.failNotEquals(Assert.java:1037)
at org.testng.Assert.assertTrue(Assert.java:45)
at org.testng.Assert.assertTrue(Assert.java:55)
at com.automation.testng.Login.LogIn_CorreoInvalido(Login.java:51)
at java.base/jdk.internal.reflect.NativeMethodAccessorImpl.invoke0(Native Method)
at java.base/jdk.internal.reflect.NativeMethodAccessorImpl.invoke(NativeMethodAccessorImpl.java:78)
at java.base/jdk.internal.reflect.DelegatingMethodAccessorImpl.invoke(DelegatingMethodAccessorImpl.java:43)
at java.base/java.lang.reflect.Method.invoke(Method.java:567)
at org.testng.internal.MethodInvocationHelper.invokeMethod(MethodInvocationHelper.java:133)
at org.testng.internal.TestInvoker.invokeMethod(TestInvoker.java:598)
at org.testng.internal.TestInvoker.invokeTestMethod(TestInvoker.java:173)
at org.testng.internal.MethodRunner.runInSequence(MethodRunner.java:46)
at org.testng.internal.TestInvoker$MethodInvocationAgent.invoke(TestInvoker.java:824)
at org.testng.internal.TestInvoker.invokeTestMethods(TestInvoker.java:146)
at org.testng.internal.TestMethodWorker.invokeTestMethods(TestMethodWorker.java:146)
at org.testng.internal.TestMethodWorker.run(TestMethodWorker.java:128)
at java.base/java.util.ArrayList.forEach(ArrayList.java:1511)
at org.testng.TestRunner.privateRun(TestRunner.java:794)
at org.testng.TestRunner.run(TestRunner.java:596)
at org.testng.SuiteRunner.runTest(SuiteRunner.java:377)
at org.testng.SuiteRunner.runSequentially(SuiteRunner.java:371)
at org.testng.SuiteRunner.privateRun(SuiteRunner.java:332)
at org.testng.SuiteRunner.run(SuiteRunner.java:276)
at org.testng.SuiteRunnerWorker.runSuite(SuiteRunnerWorker.java:53)
at org.testng.SuiteRunnerWorker.run(SuiteRunnerWorker.java:96)
at org.testng.TestNG.runSuitesSequentially(TestNG.java:1212)
at org.testng.TestNG.runSuitesLocally(TestNG.java:1134)
at org.testng.TestNG.runSuites(TestNG.java:1063)
at org.testng.TestNG.run(TestNG.java:1031)
at org.testng.remote.AbstractRemoteTestNG.run(AbstractRemoteTestNG.java:115)
at org.testng.remote.RemoteTestNG.initAndRun(RemoteTestNG.java:251)
at org.testng.remote.RemoteTestNG.main(RemoteTestNG.java:77)
]]>
            </full-stacktrace>
          </exception> <!-- java.lang.AssertionError -->
          <reporter-output>
          </reporter-output>
        </test-method> <!-- LogIn_CorreoInvalido -->
        <test-method is-config="true" signature="Cierre()[pri:0, instance:com.automation.testng.Login@4d465b11]" started-at="2021-12-15T14:16:18 PET" name="Cierre" finished-at="2021-12-15T14:16:19 PET" duration-ms="251" status="PASS">
          <reporter-output>
          </reporter-output>
        </test-method> <!-- Cierre -->
        <test-method is-config="true" signature="LoginConnection()[pri:0, instance:com.automation.testng.Login@4d465b11]" started-at="2021-12-15T14:16:19 PET" name="LoginConnection" finished-at="2021-12-15T14:16:20 PET" duration-ms="1362" status="PASS">
          <reporter-output>
          </reporter-output>
        </test-method> <!-- LoginConnection -->
        <test-method signature="LogIn_PasswordIncompleto()[pri:0, instance:com.automation.testng.Login@4d465b11]" started-at="2021-12-15T14:16:20 PET" name="LogIn_PasswordIncompleto" finished-at="2021-12-15T14:16:20 PET" duration-ms="177" status="FAIL">
          <exception class="java.lang.AssertionError">
            <message>
              <![CDATA[expected [true] but found [false]]]>
            </message>
            <full-stacktrace>
              <![CDATA[java.lang.AssertionError: expected [true] but found [false]
at org.testng.Assert.fail(Assert.java:99)
at org.testng.Assert.failNotEquals(Assert.java:1037)
at org.testng.Assert.assertTrue(Assert.java:45)
at org.testng.Assert.assertTrue(Assert.java:55)
at com.automation.testng.Login.LogIn_PasswordIncompleto(Login.java:67)
at java.base/jdk.internal.reflect.NativeMethodAccessorImpl.invoke0(Native Method)
at java.base/jdk.internal.reflect.NativeMethodAccessorImpl.invoke(NativeMethodAccessorImpl.java:78)
at java.base/jdk.internal.reflect.DelegatingMethodAccessorImpl.invoke(DelegatingMethodAccessorImpl.java:43)
at java.base/java.lang.reflect.Method.invoke(Method.java:567)
at org.testng.internal.MethodInvocationHelper.invokeMethod(MethodInvocationHelper.java:133)
at org.testng.internal.TestInvoker.invokeMethod(TestInvoker.java:598)
at org.testng.internal.TestInvoker.invokeTestMethod(TestInvoker.java:173)
at org.testng.internal.MethodRunner.runInSequence(MethodRunner.java:46)
at org.testng.internal.TestInvoker$MethodInvocationAgent.invoke(TestInvoker.java:824)
at org.testng.internal.TestInvoker.invokeTestMethods(TestInvoker.java:146)
at org.testng.internal.TestMethodWorker.invokeTestMethods(TestMethodWorker.java:146)
at org.testng.internal.TestMethodWorker.run(TestMethodWorker.java:128)
at java.base/java.util.ArrayList.forEach(ArrayList.java:1511)
at org.testng.TestRunner.privateRun(TestRunner.java:794)
at org.testng.TestRunner.run(TestRunner.java:596)
at org.testng.SuiteRunner.runTest(SuiteRunner.java:377)
at org.testng.SuiteRunner.runSequentially(SuiteRunner.java:371)
at org.testng.SuiteRunner.privateRun(SuiteRunner.java:332)
at org.testng.SuiteRunner.run(SuiteRunner.java:276)
at org.testng.SuiteRunnerWorker.runSuite(SuiteRunnerWorker.java:53)
at org.testng.SuiteRunnerWorker.run(SuiteRunnerWorker.java:96)
at org.testng.TestNG.runSuitesSequentially(TestNG.java:1212)
at org.testng.TestNG.runSuitesLocally(TestNG.java:1134)
at org.testng.TestNG.runSuites(TestNG.java:1063)
at org.testng.TestNG.run(TestNG.java:1031)
at org.testng.remote.AbstractRemoteTestNG.run(AbstractRemoteTestNG.java:115)
at org.testng.remote.RemoteTestNG.initAndRun(RemoteTestNG.java:251)
at org.testng.remote.RemoteTestNG.main(RemoteTestNG.java:77)
]]>
            </full-stacktrace>
          </exception> <!-- java.lang.AssertionError -->
          <reporter-output>
          </reporter-output>
        </test-method> <!-- LogIn_PasswordIncompleto -->
        <test-method is-config="true" signature="Cierre()[pri:0, instance:com.automation.testng.Login@4d465b11]" started-at="2021-12-15T14:16:20 PET" name="Cierre" finished-at="2021-12-15T14:16:20 PET" duration-ms="184" status="PASS">
          <reporter-output>
          </reporter-output>
        </test-method> <!-- Cierre -->
        <test-method is-config="true" signature="LoginConnection()[pri:0, instance:com.automation.testng.Login@4d465b11]" started-at="2021-12-15T14:16:20 PET" name="LoginConnection" finished-at="2021-12-15T14:16:22 PET" duration-ms="1194" status="PASS">
          <reporter-output>
          </reporter-output>
        </test-method> <!-- LoginConnection -->
        <test-method signature="LogIn_SinPass()[pri:0, instance:com.automation.testng.Login@4d465b11]" started-at="2021-12-15T14:16:22 PET" name="LogIn_SinPass" finished-at="2021-12-15T14:16:22 PET" duration-ms="242" status="FAIL">
          <exception class="java.lang.AssertionError">
            <message>
              <![CDATA[expected [true] but found [false]]]>
            </message>
            <full-stacktrace>
              <![CDATA[java.lang.AssertionError: expected [true] but found [false]
at org.testng.Assert.fail(Assert.java:99)
at org.testng.Assert.failNotEquals(Assert.java:1037)
at org.testng.Assert.assertTrue(Assert.java:45)
at org.testng.Assert.assertTrue(Assert.java:55)
at com.automation.testng.Login.LogIn_SinPass(Login.java:83)
at java.base/jdk.internal.reflect.NativeMethodAccessorImpl.invoke0(Native Method)
at java.base/jdk.internal.reflect.NativeMethodAccessorImpl.invoke(NativeMethodAccessorImpl.java:78)
at java.base/jdk.internal.reflect.DelegatingMethodAccessorImpl.invoke(DelegatingMethodAccessorImpl.java:43)
at java.base/java.lang.reflect.Method.invoke(Method.java:567)
at org.testng.internal.MethodInvocationHelper.invokeMethod(MethodInvocationHelper.java:133)
at org.testng.internal.TestInvoker.invokeMethod(TestInvoker.java:598)
at org.testng.internal.TestInvoker.invokeTestMethod(TestInvoker.java:173)
at org.testng.internal.MethodRunner.runInSequence(MethodRunner.java:46)
at org.testng.internal.TestInvoker$MethodInvocationAgent.invoke(TestInvoker.java:824)
at org.testng.internal.TestInvoker.invokeTestMethods(TestInvoker.java:146)
at org.testng.internal.TestMethodWorker.invokeTestMethods(TestMethodWorker.java:146)
at org.testng.internal.TestMethodWorker.run(TestMethodWorker.java:128)
at java.base/java.util.ArrayList.forEach(ArrayList.java:1511)
at org.testng.TestRunner.privateRun(TestRunner.java:794)
at org.testng.TestRunner.run(TestRunner.java:596)
at org.testng.SuiteRunner.runTest(SuiteRunner.java:377)
at org.testng.SuiteRunner.runSequentially(SuiteRunner.java:371)
at org.testng.SuiteRunner.privateRun(SuiteRunner.java:332)
at org.testng.SuiteRunner.run(SuiteRunner.java:276)
at org.testng.SuiteRunnerWorker.runSuite(SuiteRunnerWorker.java:53)
at org.testng.SuiteRunnerWorker.run(SuiteRunnerWorker.java:96)
at org.testng.TestNG.runSuitesSequentially(TestNG.java:1212)
at org.testng.TestNG.runSuitesLocally(TestNG.java:1134)
at org.testng.TestNG.runSuites(TestNG.java:1063)
at org.testng.TestNG.run(TestNG.java:1031)
at org.testng.remote.AbstractRemoteTestNG.run(AbstractRemoteTestNG.java:115)
at org.testng.remote.RemoteTestNG.initAndRun(RemoteTestNG.java:251)
at org.testng.remote.RemoteTestNG.main(RemoteTestNG.java:77)
]]>
            </full-stacktrace>
          </exception> <!-- java.lang.AssertionError -->
          <reporter-output>
          </reporter-output>
        </test-method> <!-- LogIn_SinPass -->
        <test-method is-config="true" signature="Cierre()[pri:0, instance:com.automation.testng.Login@4d465b11]" started-at="2021-12-15T14:16:22 PET" name="Cierre" finished-at="2021-12-15T14:16:22 PET" duration-ms="203" status="PASS">
          <reporter-output>
          </reporter-output>
        </test-method> <!-- Cierre -->
        <test-method is-config="true" signature="LoginConnection()[pri:0, instance:com.automation.testng.Login@4d465b11]" started-at="2021-12-15T14:16:22 PET" name="LoginConnection" finished-at="2021-12-15T14:16:23 PET" duration-ms="1283" status="PASS">
          <reporter-output>
          </reporter-output>
        </test-method> <!-- LoginConnection -->
        <test-method signature="LogIn_UsuarioValido()[pri:0, instance:com.automation.testng.Login@4d465b11]" started-at="2021-12-15T14:16:23 PET" name="LogIn_UsuarioValido" finished-at="2021-12-15T14:16:23 PET" duration-ms="182" status="PASS">
          <reporter-output>
          </reporter-output>
        </test-method> <!-- LogIn_UsuarioValido -->
        <test-method is-config="true" signature="Cierre()[pri:0, instance:com.automation.testng.Login@4d465b11]" started-at="2021-12-15T14:16:23 PET" name="Cierre" finished-at="2021-12-15T14:16:24 PET" duration-ms="243" status="PASS">
          <reporter-output>
          </reporter-output>
        </test-method> <!-- Cierre -->
        <test-method is-config="true" signature="LoginConnection()[pri:0, instance:com.automation.testng.Login@4d465b11]" started-at="2021-12-15T14:16:24 PET" name="LoginConnection" finished-at="2021-12-15T14:16:25 PET" duration-ms="1295" status="PASS">
          <reporter-output>
          </reporter-output>
        </test-method> <!-- LoginConnection -->
        <test-method signature="LogIn_Vacio()[pri:0, instance:com.automation.testng.Login@4d465b11]" started-at="2021-12-15T14:16:25 PET" name="LogIn_Vacio" finished-at="2021-12-15T14:16:25 PET" duration-ms="159" status="FAIL">
          <exception class="java.lang.AssertionError">
            <message>
              <![CDATA[expected [true] but found [false]]]>
            </message>
            <full-stacktrace>
              <![CDATA[java.lang.AssertionError: expected [true] but found [false]
at org.testng.Assert.fail(Assert.java:99)
at org.testng.Assert.failNotEquals(Assert.java:1037)
at org.testng.Assert.assertTrue(Assert.java:45)
at org.testng.Assert.assertTrue(Assert.java:55)
at com.automation.testng.Login.LogIn_Vacio(Login.java:99)
at java.base/jdk.internal.reflect.NativeMethodAccessorImpl.invoke0(Native Method)
at java.base/jdk.internal.reflect.NativeMethodAccessorImpl.invoke(NativeMethodAccessorImpl.java:78)
at java.base/jdk.internal.reflect.DelegatingMethodAccessorImpl.invoke(DelegatingMethodAccessorImpl.java:43)
at java.base/java.lang.reflect.Method.invoke(Method.java:567)
at org.testng.internal.MethodInvocationHelper.invokeMethod(MethodInvocationHelper.java:133)
at org.testng.internal.TestInvoker.invokeMethod(TestInvoker.java:598)
at org.testng.internal.TestInvoker.invokeTestMethod(TestInvoker.java:173)
at org.testng.internal.MethodRunner.runInSequence(MethodRunner.java:46)
at org.testng.internal.TestInvoker$MethodInvocationAgent.invoke(TestInvoker.java:824)
at org.testng.internal.TestInvoker.invokeTestMethods(TestInvoker.java:146)
at org.testng.internal.TestMethodWorker.invokeTestMethods(TestMethodWorker.java:146)
at org.testng.internal.TestMethodWorker.run(TestMethodWorker.java:128)
at java.base/java.util.ArrayList.forEach(ArrayList.java:1511)
at org.testng.TestRunner.privateRun(TestRunner.java:794)
at org.testng.TestRunner.run(TestRunner.java:596)
at org.testng.SuiteRunner.runTest(SuiteRunner.java:377)
at org.testng.SuiteRunner.runSequentially(SuiteRunner.java:371)
at org.testng.SuiteRunner.privateRun(SuiteRunner.java:332)
at org.testng.SuiteRunner.run(SuiteRunner.java:276)
at org.testng.SuiteRunnerWorker.runSuite(SuiteRunnerWorker.java:53)
at org.testng.SuiteRunnerWorker.run(SuiteRunnerWorker.java:96)
at org.testng.TestNG.runSuitesSequentially(TestNG.java:1212)
at org.testng.TestNG.runSuitesLocally(TestNG.java:1134)
at org.testng.TestNG.runSuites(TestNG.java:1063)
at org.testng.TestNG.run(TestNG.java:1031)
at org.testng.remote.AbstractRemoteTestNG.run(AbstractRemoteTestNG.java:115)
at org.testng.remote.RemoteTestNG.initAndRun(RemoteTestNG.java:251)
at org.testng.remote.RemoteTestNG.main(RemoteTestNG.java:77)
]]>
            </full-stacktrace>
          </exception> <!-- java.lang.AssertionError -->
          <reporter-output>
          </reporter-output>
        </test-method> <!-- LogIn_Vacio -->
        <test-method is-config="true" signature="Cierre()[pri:0, instance:com.automation.testng.Login@4d465b11]" started-at="2021-12-15T14:16:25 PET" name="Cierre" finished-at="2021-12-15T14:16:25 PET" duration-ms="199" status="PASS">
          <reporter-output>
          </reporter-output>
        </test-method> <!-- Cierre -->
      </class> <!-- com.automation.testng.Login -->
    </test> <!-- Default test -->
  </suite> <!-- Default suite -->
</testng-results>
